[2021-09-30 19:28:02,288] {taskinstance.py:896} INFO - Dependencies all met for <TaskInstance: etl_dag.copy_from_hdfs 2021-09-29T00:00:00+00:00 [queued]>
[2021-09-30 19:28:02,374] {taskinstance.py:896} INFO - Dependencies all met for <TaskInstance: etl_dag.copy_from_hdfs 2021-09-29T00:00:00+00:00 [queued]>
[2021-09-30 19:28:02,374] {taskinstance.py:1087} INFO - 
--------------------------------------------------------------------------------
[2021-09-30 19:28:02,375] {taskinstance.py:1088} INFO - Starting attempt 1 of 1
[2021-09-30 19:28:02,375] {taskinstance.py:1089} INFO - 
--------------------------------------------------------------------------------
[2021-09-30 19:28:02,393] {taskinstance.py:1107} INFO - Executing <Task(PythonOperator): copy_from_hdfs> on 2021-09-29T00:00:00+00:00
[2021-09-30 19:28:02,398] {standard_task_runner.py:52} INFO - Started process 1716056 to run task
[2021-09-30 19:28:02,403] {standard_task_runner.py:76} INFO - Running: ['airflow', 'tasks', 'run', 'etl_dag', 'copy_from_hdfs', '2021-09-29T00:00:00+00:00', '--job-id', '440', '--pool', 'default_pool', '--raw', '--subdir', 'DAGS_FOLDER/etl_dag.py', '--cfg-path', '/tmp/tmpurgyrbe3', '--error-file', '/tmp/tmpx8fcyq8h']
[2021-09-30 19:28:02,403] {standard_task_runner.py:77} INFO - Job 440: Subtask copy_from_hdfs
[2021-09-30 19:28:02,505] {logging_mixin.py:104} INFO - Running <TaskInstance: etl_dag.copy_from_hdfs 2021-09-29T00:00:00+00:00 [running]> on host kseniya-B85M-D3V
[2021-09-30 19:28:02,620] {taskinstance.py:1300} INFO - Exporting the following env vars:
AIRFLOW_CTX_DAG_OWNER=airflow
AIRFLOW_CTX_DAG_ID=etl_dag
AIRFLOW_CTX_TASK_ID=copy_from_hdfs
AIRFLOW_CTX_EXECUTION_DATE=2021-09-29T00:00:00+00:00
AIRFLOW_CTX_DAG_RUN_ID=scheduled__2021-09-29T00:00:00+00:00
[2021-09-30 19:28:17,669] {local_task_job.py:197} WARNING - State of this instance has been externally set to removed. Terminating instance.
[2021-09-30 19:28:17,722] {process_utils.py:100} INFO - Sending Signals.SIGTERM to GPID 1716056
[2021-09-30 19:28:17,723] {taskinstance.py:1284} ERROR - Received SIGTERM. Terminating subprocesses.
[2021-09-30 19:28:17,723] {java_gateway.py:1210} INFO - Error while receiving.
Traceback (most recent call last):
  File "/home/kseniya/.local/lib/python3.8/site-packages/py4j/java_gateway.py", line 1200, in send_command
    answer = smart_decode(self.stream.readline()[:-1])
  File "/usr/lib/python3.8/socket.py", line 669, in readinto
    return self._sock.recv_into(b)
  File "/usr/local/lib/python3.8/dist-packages/airflow/models/taskinstance.py", line 1286, in signal_handler
    raise AirflowException("Task received SIGTERM signal")
airflow.exceptions.AirflowException: Task received SIGTERM signal
[2021-09-30 19:28:17,725] {java_gateway.py:1050} ERROR - Exception while sending command.
Traceback (most recent call last):
  File "/home/kseniya/.local/lib/python3.8/site-packages/py4j/java_gateway.py", line 1200, in send_command
    answer = smart_decode(self.stream.readline()[:-1])
  File "/usr/lib/python3.8/socket.py", line 669, in readinto
    return self._sock.recv_into(b)
  File "/usr/local/lib/python3.8/dist-packages/airflow/models/taskinstance.py", line 1286, in signal_handler
    raise AirflowException("Task received SIGTERM signal")
airflow.exceptions.AirflowException: Task received SIGTERM signal

During handling of the above exception, another exception occurred:

Traceback (most recent call last):
  File "/home/kseniya/.local/lib/python3.8/site-packages/py4j/java_gateway.py", line 1033, in send_command
    response = connection.send_command(command)
  File "/home/kseniya/.local/lib/python3.8/site-packages/py4j/java_gateway.py", line 1211, in send_command
    raise Py4JNetworkError(
py4j.protocol.Py4JNetworkError: Error while receiving
[2021-09-30 19:28:17,726] {taskinstance.py:1501} ERROR - Task failed with exception
Traceback (most recent call last):
  File "/usr/local/lib/python3.8/dist-packages/airflow/models/taskinstance.py", line 1157, in _run_raw_task
    self._prepare_and_execute_task_with_callbacks(context, task)
  File "/usr/local/lib/python3.8/dist-packages/airflow/models/taskinstance.py", line 1331, in _prepare_and_execute_task_with_callbacks
    result = self._execute_task(context, task_copy)
  File "/usr/local/lib/python3.8/dist-packages/airflow/models/taskinstance.py", line 1361, in _execute_task
    result = task_copy.execute(context=context)
  File "/usr/local/lib/python3.8/dist-packages/airflow/operators/python.py", line 150, in execute
    return_value = self.execute_callable()
  File "/usr/local/lib/python3.8/dist-packages/airflow/operators/python.py", line 161, in execute_callable
    return self.python_callable(*self.op_args, **self.op_kwargs)
  File "/home/kseniya/airflow/dags/scripts/hdfs_task.py", line 4, in hdfs_task
    df = sparkSession.read.csv("hdfs://namenode:9000/nn_all.csv")
  File "/home/kseniya/.local/lib/python3.8/site-packages/pyspark/sql/readwriter.py", line 737, in csv
    return self._df(self._jreader.csv(self._spark._sc._jvm.PythonUtils.toSeq(path)))
  File "/home/kseniya/.local/lib/python3.8/site-packages/py4j/java_gateway.py", line 1304, in __call__
    return_value = get_return_value(
  File "/home/kseniya/.local/lib/python3.8/site-packages/pyspark/sql/utils.py", line 111, in deco
    return f(*a, **kw)
  File "/home/kseniya/.local/lib/python3.8/site-packages/py4j/protocol.py", line 334, in get_return_value
    raise Py4JError(
py4j.protocol.Py4JError: An error occurred while calling o26.csv
[2021-09-30 19:28:17,731] {taskinstance.py:1544} INFO - Marking task as FAILED. dag_id=etl_dag, task_id=copy_from_hdfs, execution_date=20210929T000000, start_date=20210930T162802, end_date=20210930T162817
[2021-09-30 19:28:18,253] {process_utils.py:66} INFO - Process psutil.Process(pid=1716056, status='terminated', exitcode=1, started='19:28:02') (1716056) terminated with exit code 1
[2021-09-30 19:28:18,827] {process_utils.py:66} INFO - Process psutil.Process(pid=1716079, status='terminated', started='19:28:02') (1716079) terminated with exit code None
