[2021-09-30 19:20:53,464] {taskinstance.py:896} INFO - Dependencies all met for <TaskInstance: etl_dag.copy_from_hdfs 2021-09-28T00:30:00+00:00 [queued]>
[2021-09-30 19:20:53,501] {taskinstance.py:896} INFO - Dependencies all met for <TaskInstance: etl_dag.copy_from_hdfs 2021-09-28T00:30:00+00:00 [queued]>
[2021-09-30 19:20:53,502] {taskinstance.py:1087} INFO - 
--------------------------------------------------------------------------------
[2021-09-30 19:20:53,502] {taskinstance.py:1088} INFO - Starting attempt 1 of 1
[2021-09-30 19:20:53,502] {taskinstance.py:1089} INFO - 
--------------------------------------------------------------------------------
[2021-09-30 19:20:53,520] {taskinstance.py:1107} INFO - Executing <Task(PythonOperator): copy_from_hdfs> on 2021-09-28T00:30:00+00:00
[2021-09-30 19:20:53,525] {standard_task_runner.py:52} INFO - Started process 1697207 to run task
[2021-09-30 19:20:53,530] {standard_task_runner.py:76} INFO - Running: ['airflow', 'tasks', 'run', 'etl_dag', 'copy_from_hdfs', '2021-09-28T00:30:00+00:00', '--job-id', '415', '--pool', 'default_pool', '--raw', '--subdir', 'DAGS_FOLDER/etl_dag.py', '--cfg-path', '/tmp/tmpjw1hnr5h', '--error-file', '/tmp/tmp48v1re03']
[2021-09-30 19:20:53,530] {standard_task_runner.py:77} INFO - Job 415: Subtask copy_from_hdfs
[2021-09-30 19:20:53,582] {logging_mixin.py:104} INFO - Running <TaskInstance: etl_dag.copy_from_hdfs 2021-09-28T00:30:00+00:00 [running]> on host kseniya-B85M-D3V
[2021-09-30 19:20:53,704] {taskinstance.py:1300} INFO - Exporting the following env vars:
AIRFLOW_CTX_DAG_OWNER=airflow
AIRFLOW_CTX_DAG_ID=etl_dag
AIRFLOW_CTX_TASK_ID=copy_from_hdfs
AIRFLOW_CTX_EXECUTION_DATE=2021-09-28T00:30:00+00:00
AIRFLOW_CTX_DAG_RUN_ID=scheduled__2021-09-28T00:30:00+00:00
[2021-09-30 19:21:15,785] {python.py:151} INFO - Done. Returned value was: None
[2021-09-30 19:21:15,821] {taskinstance.py:1204} INFO - Marking task as SUCCESS. dag_id=etl_dag, task_id=copy_from_hdfs, execution_date=20210928T003000, start_date=20210930T162053, end_date=20210930T162115
[2021-09-30 19:21:15,880] {taskinstance.py:1265} INFO - 0 downstream tasks scheduled from follow-on schedule check
[2021-09-30 19:21:15,893] {local_task_job.py:149} INFO - Task exited with return code 0
[2021-09-30 19:22:10,217] {taskinstance.py:896} INFO - Dependencies all met for <TaskInstance: etl_dag.copy_from_hdfs 2021-09-28T00:30:00+00:00 [queued]>
[2021-09-30 19:22:10,283] {taskinstance.py:896} INFO - Dependencies all met for <TaskInstance: etl_dag.copy_from_hdfs 2021-09-28T00:30:00+00:00 [queued]>
[2021-09-30 19:22:10,283] {taskinstance.py:1087} INFO - 
--------------------------------------------------------------------------------
[2021-09-30 19:22:10,283] {taskinstance.py:1088} INFO - Starting attempt 1 of 1
[2021-09-30 19:22:10,284] {taskinstance.py:1089} INFO - 
--------------------------------------------------------------------------------
[2021-09-30 19:22:10,301] {taskinstance.py:1107} INFO - Executing <Task(PythonOperator): copy_from_hdfs> on 2021-09-28T00:30:00+00:00
[2021-09-30 19:22:10,305] {standard_task_runner.py:52} INFO - Started process 1700537 to run task
[2021-09-30 19:22:10,332] {standard_task_runner.py:76} INFO - Running: ['airflow', 'tasks', 'run', 'etl_dag', 'copy_from_hdfs', '2021-09-28T00:30:00+00:00', '--job-id', '420', '--pool', 'default_pool', '--raw', '--subdir', 'DAGS_FOLDER/etl_dag.py', '--cfg-path', '/tmp/tmpb4vdb3a8', '--error-file', '/tmp/tmpa4vgkud6']
[2021-09-30 19:22:10,333] {standard_task_runner.py:77} INFO - Job 420: Subtask copy_from_hdfs
[2021-09-30 19:22:10,457] {logging_mixin.py:104} INFO - Running <TaskInstance: etl_dag.copy_from_hdfs 2021-09-28T00:30:00+00:00 [running]> on host kseniya-B85M-D3V
[2021-09-30 19:22:10,683] {taskinstance.py:1300} INFO - Exporting the following env vars:
AIRFLOW_CTX_DAG_OWNER=airflow
AIRFLOW_CTX_DAG_ID=etl_dag
AIRFLOW_CTX_TASK_ID=copy_from_hdfs
AIRFLOW_CTX_EXECUTION_DATE=2021-09-28T00:30:00+00:00
AIRFLOW_CTX_DAG_RUN_ID=scheduled__2021-09-28T00:30:00+00:00
[2021-09-30 19:22:40,814] {local_task_job.py:197} WARNING - State of this instance has been externally set to removed. Terminating instance.
[2021-09-30 19:22:40,849] {process_utils.py:100} INFO - Sending Signals.SIGTERM to GPID 1700537
[2021-09-30 19:22:40,849] {taskinstance.py:1284} ERROR - Received SIGTERM. Terminating subprocesses.
[2021-09-30 19:22:40,850] {java_gateway.py:1210} INFO - Error while receiving.
Traceback (most recent call last):
  File "/home/kseniya/.local/lib/python3.8/site-packages/py4j/java_gateway.py", line 1200, in send_command
    answer = smart_decode(self.stream.readline()[:-1])
  File "/usr/lib/python3.8/socket.py", line 669, in readinto
    return self._sock.recv_into(b)
  File "/usr/local/lib/python3.8/dist-packages/airflow/models/taskinstance.py", line 1286, in signal_handler
    raise AirflowException("Task received SIGTERM signal")
airflow.exceptions.AirflowException: Task received SIGTERM signal
[2021-09-30 19:22:40,851] {java_gateway.py:1050} ERROR - Exception while sending command.
Traceback (most recent call last):
  File "/home/kseniya/.local/lib/python3.8/site-packages/py4j/java_gateway.py", line 1200, in send_command
    answer = smart_decode(self.stream.readline()[:-1])
  File "/usr/lib/python3.8/socket.py", line 669, in readinto
    return self._sock.recv_into(b)
  File "/usr/local/lib/python3.8/dist-packages/airflow/models/taskinstance.py", line 1286, in signal_handler
    raise AirflowException("Task received SIGTERM signal")
airflow.exceptions.AirflowException: Task received SIGTERM signal

During handling of the above exception, another exception occurred:

Traceback (most recent call last):
  File "/home/kseniya/.local/lib/python3.8/site-packages/py4j/java_gateway.py", line 1033, in send_command
    response = connection.send_command(command)
  File "/home/kseniya/.local/lib/python3.8/site-packages/py4j/java_gateway.py", line 1211, in send_command
    raise Py4JNetworkError(
py4j.protocol.Py4JNetworkError: Error while receiving
[2021-09-30 19:22:40,900] {taskinstance.py:1501} ERROR - Task failed with exception
Traceback (most recent call last):
  File "/usr/local/lib/python3.8/dist-packages/airflow/models/taskinstance.py", line 1157, in _run_raw_task
    self._prepare_and_execute_task_with_callbacks(context, task)
  File "/usr/local/lib/python3.8/dist-packages/airflow/models/taskinstance.py", line 1331, in _prepare_and_execute_task_with_callbacks
    result = self._execute_task(context, task_copy)
  File "/usr/local/lib/python3.8/dist-packages/airflow/models/taskinstance.py", line 1361, in _execute_task
    result = task_copy.execute(context=context)
  File "/usr/local/lib/python3.8/dist-packages/airflow/operators/python.py", line 150, in execute
    return_value = self.execute_callable()
  File "/usr/local/lib/python3.8/dist-packages/airflow/operators/python.py", line 161, in execute_callable
    return self.python_callable(*self.op_args, **self.op_kwargs)
  File "/home/kseniya/airflow/dags/scripts/hdfs_task.py", line 4, in hdfs_task
    df = sparkSession.read.csv("hdfs://namenode:9000/nn_all.csv")
  File "/home/kseniya/.local/lib/python3.8/site-packages/pyspark/sql/readwriter.py", line 737, in csv
    return self._df(self._jreader.csv(self._spark._sc._jvm.PythonUtils.toSeq(path)))
  File "/home/kseniya/.local/lib/python3.8/site-packages/py4j/java_gateway.py", line 1304, in __call__
    return_value = get_return_value(
  File "/home/kseniya/.local/lib/python3.8/site-packages/pyspark/sql/utils.py", line 111, in deco
    return f(*a, **kw)
  File "/home/kseniya/.local/lib/python3.8/site-packages/py4j/protocol.py", line 334, in get_return_value
    raise Py4JError(
py4j.protocol.Py4JError: An error occurred while calling o26.csv
[2021-09-30 19:22:40,902] {taskinstance.py:1544} INFO - Marking task as FAILED. dag_id=etl_dag, task_id=copy_from_hdfs, execution_date=20210928T003000, start_date=20210930T162210, end_date=20210930T162240
[2021-09-30 19:22:41,027] {process_utils.py:66} INFO - Process psutil.Process(pid=1700537, status='terminated', exitcode=1, started='19:22:10') (1700537) terminated with exit code 1
[2021-09-30 19:22:41,875] {process_utils.py:66} INFO - Process psutil.Process(pid=1700567, status='terminated', started='19:22:10') (1700567) terminated with exit code None
[2021-09-30 19:22:41,876] {process_utils.py:66} INFO - Process psutil.Process(pid=1700576, status='terminated', started='19:22:10') (1700576) terminated with exit code None
[2021-09-30 19:23:59,056] {taskinstance.py:896} INFO - Dependencies all met for <TaskInstance: etl_dag.copy_from_hdfs 2021-09-28T00:30:00+00:00 [queued]>
[2021-09-30 19:23:59,111] {taskinstance.py:896} INFO - Dependencies all met for <TaskInstance: etl_dag.copy_from_hdfs 2021-09-28T00:30:00+00:00 [queued]>
[2021-09-30 19:23:59,111] {taskinstance.py:1087} INFO - 
--------------------------------------------------------------------------------
[2021-09-30 19:23:59,111] {taskinstance.py:1088} INFO - Starting attempt 1 of 1
[2021-09-30 19:23:59,111] {taskinstance.py:1089} INFO - 
--------------------------------------------------------------------------------
[2021-09-30 19:23:59,157] {taskinstance.py:1107} INFO - Executing <Task(PythonOperator): copy_from_hdfs> on 2021-09-28T00:30:00+00:00
[2021-09-30 19:23:59,161] {standard_task_runner.py:52} INFO - Started process 1704696 to run task
[2021-09-30 19:23:59,174] {standard_task_runner.py:76} INFO - Running: ['airflow', 'tasks', 'run', 'etl_dag', 'copy_from_hdfs', '2021-09-28T00:30:00+00:00', '--job-id', '426', '--pool', 'default_pool', '--raw', '--subdir', 'DAGS_FOLDER/etl_dag.py', '--cfg-path', '/tmp/tmpiqxm4m9p', '--error-file', '/tmp/tmp4d39kg0t']
[2021-09-30 19:23:59,174] {standard_task_runner.py:77} INFO - Job 426: Subtask copy_from_hdfs
[2021-09-30 19:23:59,259] {logging_mixin.py:104} INFO - Running <TaskInstance: etl_dag.copy_from_hdfs 2021-09-28T00:30:00+00:00 [running]> on host kseniya-B85M-D3V
[2021-09-30 19:23:59,375] {taskinstance.py:1300} INFO - Exporting the following env vars:
AIRFLOW_CTX_DAG_OWNER=airflow
AIRFLOW_CTX_DAG_ID=etl_dag
AIRFLOW_CTX_TASK_ID=copy_from_hdfs
AIRFLOW_CTX_EXECUTION_DATE=2021-09-28T00:30:00+00:00
AIRFLOW_CTX_DAG_RUN_ID=scheduled__2021-09-28T00:30:00+00:00
[2021-09-30 19:24:09,376] {local_task_job.py:197} WARNING - State of this instance has been externally set to removed. Terminating instance.
[2021-09-30 19:24:09,455] {process_utils.py:100} INFO - Sending Signals.SIGTERM to GPID 1704696
[2021-09-30 19:24:09,456] {taskinstance.py:1284} ERROR - Received SIGTERM. Terminating subprocesses.
[2021-09-30 19:24:09,456] {java_gateway.py:1210} INFO - Error while receiving.
Traceback (most recent call last):
  File "/home/kseniya/.local/lib/python3.8/site-packages/py4j/java_gateway.py", line 1200, in send_command
    answer = smart_decode(self.stream.readline()[:-1])
  File "/usr/lib/python3.8/socket.py", line 669, in readinto
    return self._sock.recv_into(b)
  File "/usr/local/lib/python3.8/dist-packages/airflow/models/taskinstance.py", line 1286, in signal_handler
    raise AirflowException("Task received SIGTERM signal")
airflow.exceptions.AirflowException: Task received SIGTERM signal
[2021-09-30 19:24:09,457] {java_gateway.py:1050} ERROR - Exception while sending command.
Traceback (most recent call last):
  File "/home/kseniya/.local/lib/python3.8/site-packages/py4j/java_gateway.py", line 1200, in send_command
    answer = smart_decode(self.stream.readline()[:-1])
  File "/usr/lib/python3.8/socket.py", line 669, in readinto
    return self._sock.recv_into(b)
  File "/usr/local/lib/python3.8/dist-packages/airflow/models/taskinstance.py", line 1286, in signal_handler
    raise AirflowException("Task received SIGTERM signal")
airflow.exceptions.AirflowException: Task received SIGTERM signal

During handling of the above exception, another exception occurred:

Traceback (most recent call last):
  File "/home/kseniya/.local/lib/python3.8/site-packages/py4j/java_gateway.py", line 1033, in send_command
    response = connection.send_command(command)
  File "/home/kseniya/.local/lib/python3.8/site-packages/py4j/java_gateway.py", line 1211, in send_command
    raise Py4JNetworkError(
py4j.protocol.Py4JNetworkError: Error while receiving
[2021-09-30 19:24:09,503] {taskinstance.py:1501} ERROR - Task failed with exception
Traceback (most recent call last):
  File "/usr/local/lib/python3.8/dist-packages/airflow/models/taskinstance.py", line 1157, in _run_raw_task
    self._prepare_and_execute_task_with_callbacks(context, task)
  File "/usr/local/lib/python3.8/dist-packages/airflow/models/taskinstance.py", line 1331, in _prepare_and_execute_task_with_callbacks
    result = self._execute_task(context, task_copy)
  File "/usr/local/lib/python3.8/dist-packages/airflow/models/taskinstance.py", line 1361, in _execute_task
    result = task_copy.execute(context=context)
  File "/usr/local/lib/python3.8/dist-packages/airflow/operators/python.py", line 150, in execute
    return_value = self.execute_callable()
  File "/usr/local/lib/python3.8/dist-packages/airflow/operators/python.py", line 161, in execute_callable
    return self.python_callable(*self.op_args, **self.op_kwargs)
  File "/home/kseniya/airflow/dags/scripts/hdfs_task.py", line 4, in hdfs_task
    df = sparkSession.read.csv("hdfs://namenode:9000/nn_all.csv")
  File "/home/kseniya/.local/lib/python3.8/site-packages/pyspark/sql/readwriter.py", line 737, in csv
    return self._df(self._jreader.csv(self._spark._sc._jvm.PythonUtils.toSeq(path)))
  File "/home/kseniya/.local/lib/python3.8/site-packages/py4j/java_gateway.py", line 1304, in __call__
    return_value = get_return_value(
  File "/home/kseniya/.local/lib/python3.8/site-packages/pyspark/sql/utils.py", line 111, in deco
    return f(*a, **kw)
  File "/home/kseniya/.local/lib/python3.8/site-packages/py4j/protocol.py", line 334, in get_return_value
    raise Py4JError(
py4j.protocol.Py4JError: An error occurred while calling o26.csv
[2021-09-30 19:24:09,505] {taskinstance.py:1544} INFO - Marking task as FAILED. dag_id=etl_dag, task_id=copy_from_hdfs, execution_date=20210928T003000, start_date=20210930T162359, end_date=20210930T162409
[2021-09-30 19:24:09,595] {process_utils.py:66} INFO - Process psutil.Process(pid=1704696, status='terminated', exitcode=1, started='19:23:59') (1704696) terminated with exit code 1
[2021-09-30 19:24:10,758] {process_utils.py:66} INFO - Process psutil.Process(pid=1704721, status='terminated', started='19:23:59') (1704721) terminated with exit code None
