[2021-09-30 19:26:44,906] {taskinstance.py:896} INFO - Dependencies all met for <TaskInstance: etl_dag.copy_from_hdfs 2021-09-28T00:01:00+00:00 [queued]>
[2021-09-30 19:26:44,967] {taskinstance.py:896} INFO - Dependencies all met for <TaskInstance: etl_dag.copy_from_hdfs 2021-09-28T00:01:00+00:00 [queued]>
[2021-09-30 19:26:44,968] {taskinstance.py:1087} INFO - 
--------------------------------------------------------------------------------
[2021-09-30 19:26:44,970] {taskinstance.py:1088} INFO - Starting attempt 3 of 1
[2021-09-30 19:26:44,970] {taskinstance.py:1089} INFO - 
--------------------------------------------------------------------------------
[2021-09-30 19:26:45,010] {taskinstance.py:1107} INFO - Executing <Task(PythonOperator): copy_from_hdfs> on 2021-09-28T00:01:00+00:00
[2021-09-30 19:26:45,023] {standard_task_runner.py:52} INFO - Started process 1712437 to run task
[2021-09-30 19:26:45,067] {standard_task_runner.py:76} INFO - Running: ['airflow', 'tasks', 'run', 'etl_dag', 'copy_from_hdfs', '2021-09-28T00:01:00+00:00', '--job-id', '437', '--pool', 'default_pool', '--raw', '--subdir', 'DAGS_FOLDER/etl_dag.py', '--cfg-path', '/tmp/tmphi2311_g', '--error-file', '/tmp/tmpx40o7du4']
[2021-09-30 19:26:45,068] {standard_task_runner.py:77} INFO - Job 437: Subtask copy_from_hdfs
[2021-09-30 19:26:45,178] {logging_mixin.py:104} INFO - Running <TaskInstance: etl_dag.copy_from_hdfs 2021-09-28T00:01:00+00:00 [running]> on host kseniya-B85M-D3V
[2021-09-30 19:26:45,351] {taskinstance.py:1300} INFO - Exporting the following env vars:
AIRFLOW_CTX_DAG_OWNER=airflow
AIRFLOW_CTX_DAG_ID=etl_dag
AIRFLOW_CTX_TASK_ID=copy_from_hdfs
AIRFLOW_CTX_EXECUTION_DATE=2021-09-28T00:01:00+00:00
AIRFLOW_CTX_DAG_RUN_ID=scheduled__2021-09-28T00:01:00+00:00
[2021-09-30 19:26:50,161] {local_task_job.py:197} WARNING - State of this instance has been externally set to None. Terminating instance.
[2021-09-30 19:26:50,272] {process_utils.py:100} INFO - Sending Signals.SIGTERM to GPID 1712437
[2021-09-30 19:26:50,272] {taskinstance.py:1284} ERROR - Received SIGTERM. Terminating subprocesses.
[2021-09-30 19:26:50,291] {taskinstance.py:1501} ERROR - Task failed with exception
Traceback (most recent call last):
  File "/usr/local/lib/python3.8/dist-packages/airflow/models/taskinstance.py", line 1157, in _run_raw_task
    self._prepare_and_execute_task_with_callbacks(context, task)
  File "/usr/local/lib/python3.8/dist-packages/airflow/models/taskinstance.py", line 1331, in _prepare_and_execute_task_with_callbacks
    result = self._execute_task(context, task_copy)
  File "/usr/local/lib/python3.8/dist-packages/airflow/models/taskinstance.py", line 1361, in _execute_task
    result = task_copy.execute(context=context)
  File "/usr/local/lib/python3.8/dist-packages/airflow/operators/python.py", line 150, in execute
    return_value = self.execute_callable()
  File "/usr/local/lib/python3.8/dist-packages/airflow/operators/python.py", line 161, in execute_callable
    return self.python_callable(*self.op_args, **self.op_kwargs)
  File "/home/kseniya/airflow/dags/scripts/hdfs_task.py", line 3, in hdfs_task
    sparkSession = SparkSession.builder.appName("example-pyspark-read-and-write").getOrCreate()
  File "/home/kseniya/.local/lib/python3.8/site-packages/pyspark/sql/session.py", line 228, in getOrCreate
    sc = SparkContext.getOrCreate(sparkConf)
  File "/home/kseniya/.local/lib/python3.8/site-packages/pyspark/context.py", line 384, in getOrCreate
    SparkContext(conf=conf or SparkConf())
  File "/home/kseniya/.local/lib/python3.8/site-packages/pyspark/context.py", line 144, in __init__
    SparkContext._ensure_initialized(self, gateway=gateway, conf=conf)
  File "/home/kseniya/.local/lib/python3.8/site-packages/pyspark/context.py", line 331, in _ensure_initialized
    SparkContext._gateway = gateway or launch_gateway(conf)
  File "/home/kseniya/.local/lib/python3.8/site-packages/pyspark/java_gateway.py", line 105, in launch_gateway
    time.sleep(0.1)
  File "/usr/local/lib/python3.8/dist-packages/airflow/models/taskinstance.py", line 1286, in signal_handler
    raise AirflowException("Task received SIGTERM signal")
airflow.exceptions.AirflowException: Task received SIGTERM signal
[2021-09-30 19:26:50,312] {taskinstance.py:1544} INFO - Marking task as FAILED. dag_id=etl_dag, task_id=copy_from_hdfs, execution_date=20210928T000100, start_date=20210930T162644, end_date=20210930T162650
[2021-09-30 19:26:50,422] {process_utils.py:66} INFO - Process psutil.Process(pid=1712450, status='terminated', started='19:26:45') (1712450) terminated with exit code None
[2021-09-30 19:26:50,422] {process_utils.py:66} INFO - Process psutil.Process(pid=1712437, status='terminated', exitcode=1, started='19:26:44') (1712437) terminated with exit code 1
